Workbook

Sheet American journal voucher
G1: =H2-G2 -> 59799 | I1: =J2-I2 -> 388408 | K1: =L2-K2 -> -34124.8 | M1: =N2-M2 -> 1087750 | O1: =O2-P2 -> 23305332 | Q1: =R2-Q2 -> 3154668 | S1: =T2-S2 -> 3309592 | U1: =V2-U2 -> 1832308 | W1: =X2-W2 -> 54895 | Y1: =Y2-Z2 -> 5579853 | AA1: =AB2-AA2 -> 0 | AC1: =AC2-AD2 -> 0 | AE1: =AE2-AF2 -> 0 | AG1: =AH2-AG2 -> 0 | AI1: =AJ2-AI2 -> 0 | AK1: =AL2-AK2 -> -4483795.9 | AM1: =AN2-AM2 -> 326070 | AO1: =AP2-AO2 -> 1170982 | AQ1: =AR2-AQ2 -> 4090461.8 | AS1: =AT2-AS2 -> 8786830 | AW1: =AX2-AW2 -> 5121874.9 | AY1: =AZ2-AY2 -> 944383 | BA1: =BA2-BB2 -> 0 | BC1: =BD2-BC2 -> 5863798.8 | BE1: =BF2-BE2 -> 0 | BG1: =BH2-BG2 -> 0 | BI1: =BJ2-BI2 -> 0 | BK1: =BK2-BL2 -> 0 | BM1: =BN2-BM2 -> 0 | BO1: =BO2-BP2 -> 0 | BQ1: =BR2-BQ2 -> -700 | BS1: =BT2-BS2 -> 755676
E2: =SUBTOTAL(9,E5:E5097) -> 1.9928317e+08 | F2: =SUBTOTAL(9,F5:F5097) -> 1.9928317e+08 | G2: =SUBTOTAL(9,G5:G5097) -> 5066015 | H2: =SUBTOTAL(9,H5:H5097) -> 5125814 | I2: =SUBTOTAL(9,I5:I5097) -> 0 | J2: =SUBTOTAL(9,J5:J5097) -> 388408 | K2: =SUBTOTAL(9,K5:K5097) -> 301199.8 | L2: =SUBTOTAL(9,L5:L5097) -> 267075 | ... CF2: =SUBTOTAL(9,CF5:CF5097) -> 0
A3: Ref | B3: Date | C3: Description | D3: Net | E3: Total | G3: Cash | I3: Bank | K3: Vodafon Cash | M3: Inventory | O3: Sales | Q3: Instapay 2 | S3: Paymob | U3: Value | W3: Gift Card | Y3: Share holder's | AA3: Depreciation | AC3: Capital | AE3: Retained earning | AG3: Prepared Expenses | AI3: Fixed assets | AK3: Opreation | AM3: Shipping | AO3: Administrative Expenses | AQ3: Advance to employees | AS3: Cost | AU3: Purchasing | AW3: Discount | AY3: Refund | BA3: Suppliers | BC3: Markting | BE3: Bank Masr | BG3: Bank interest | BI3: other Ep | BK3: Bank interest cr | BM3: p&l | BO3: deposits revenue | BQ3: سلف | BS3: SYMPL | BU3: INSTAPAY
E4: Credit | F4: Debit | G4: Credit | H4: Debit | I4: Credit | J4: Debit | K4: Credit | L4: Debit | M4: Credit | N4: Debit | O4: Credit | P4: Debit | Q4: Credit | R4: Debit | S4: Credit | T4: Debit | U4: Credit | V4: Debit | W4: Credit | X4: Debit | Y4: Credit | Z4: Debit | AA4: Credit | AB4: Debit | AC4: Credit | AD4: Debit | AE4: Credit | AF4: Debit | AG4: Credit | AH4: Debit | AI4: Credit | AJ4: Debit | AK4: Credit | AL4: Debit | AM4: Credit | AN4: Debit | AO4: Credit | AP4: Debit | AQ4: Credit | AR4: Debit | AS4: Credit | AT4: Debit | AU4: Credit | AV4: Debit | AW4: Credit | AX4: Debit | AY4: Credit | AZ4: Debit | BA4: Credit | BB4: Debit | BC4: Credit | BD4: Debit | BE4: Credit | BF4: Debit | BG4: Credit | BH4: Debit | BI4: Credit | BJ4: Debit | BK4: Credit | BL4: Debit | BM4: Credit | BN4: Debit | BO4: credit | BP4: Debit | BQ4: credit | BR4: Debit | BS4: Credit | BT4: Debit | BU4: Credit | BV4: Debit | BW4: credit | BX4: Debit | BY4: Credit | BZ4: Debit | CA4: Credit | CB4: Debit | CC4: Credit | CD4: Debit | CE4: Credit | CF4: Debit
B5: 0 | C5: op | D5: =F5-E5 -> 0 | E5: =G5+I5+CC266+K5+M5+O5+Q5+S5+U5+W5+Y5+AA5+AC5+AE5+AG5+AI5+AK5+AM5+AO5+AQ5+AS5+AU5+AW5+AY5+BA5+BC5+BE5+BG5+BI5+BK5+BM5+BO5+BQ5+BS5+BU5+BW5+BY5+CA5+CE266 -> 0 | F5: =H5+J5+L5+CD266+N5+P5+R5+T5+V5+X5+Z5+AB5+AD5+AF5+AH5+AJ5+AL5+AN5+AP5+AR5+AT5+AV5+AX5+AZ5+BB5+BD5+BF5+BH5+BJ5+BL5+BN5+BP5+BR5+BT5+BV5+BX5+BZ5+CB5+CF266 -> 0
A6: 1 | B6: 46023 | C6: Sales | D6: =F6-E6 -> 0 | E6: =G6+I6+CC267+K6+M6+O6+Q6+S6+U6+W6+Y6+AA6+AC6+AE6+AG6+AI6+AK6+AM6+AO6+AQ6+AS6+AU6+AW6+AY6+BA6+BC6+BE6+BG6+BI6+BK6+BM6+BO6+BQ6+BS6+BU6+BW6+BY6+CA6+CE267 -> 552915 | F6: =H6+J6+L6+CD267+N6+P6+R6+T6+V6+X6+Z6+AB6+AD6+AF6+AH6+AJ6+AL6+AN6+AP6+AR6+AT6+AV6+AX6+AZ6+BB6+BD6+BF6+BH6+BJ6+BL6+BN6+BP6+BR6+BT6+BV6+BX6+BZ6+CB6+CF267 -> 552915 | O6: 509471 | AK6: 43444 | AL6: 509471 | AX6: 43444
A7: 2 | B7: 46023 | C7: Returns | D7: =F7-E7 -> 0 | E7: =G7+I7+CC268+K7+M7+O7+Q7+S7+U7+W7+Y7+AA7+AC7+AE7+AG7+AI7+AK7+AM7+AO7+AQ7+AS7+AU7+AW7+AY7+BA7+BC7+BE7+BG7+BI7+BK7+BM7+BO7+BQ7+BS7+BU7+BW7+BY7+CA7+CE268 -> 296659 | F7: =H7+J7+L7+CD268+N7+P7+R7+T7+V7+X7+Z7+AB7+AD7+AF7+AH7+AJ7+AL7+AN7+AP7+AR7+AT7+AV7+AX7+AZ7+BB7+BD7+BF7+BH7+BJ7+BL7+BN7+BP7+BR7+BT7+BV7+BX7+BZ7+CB7+CF268 -> 296659 | P7: 296659 | AQ7: 296659
A8: 3 | B8: 46023 | C8: Returns Cost | D8: =F8-E8 -> 0 | E8: =G8+I8+CC269+K8+M8+O8+Q8+S8+U8+W8+Y8+AA8+AC8+AE8+AG8+AI8+AK8+AM8+AO8+AQ8+AS8+AU8+AW8+AY8+BA8+BC8+BE8+BG8+BI8+BK8+BM8+BO8+BQ8+BS8+BU8+BW8+BY8+CA8+CE269 -> 144100 | F8: =H8+J8+L8+CD269+N8+P8+R8+T8+V8+X8+Z8+AB8+AD8+AF8+AH8+AJ8+AL8+AN8+AP8+AR8+AT8+AV8+AX8+AZ8+BB8+BD8+BF8+BH8+BJ8+BL8+BN8+BP8+BR8+BT8+BV8+BX8+BZ8+CB8+CF269 -> 144100 | N8: 144100 | AS8: 144100
A9: 4 | B9: 46023 | C9: Cost | D9: =F9-E9 -> 0 | E9: =G9+I9+CC270+K9+M9+O9+Q9+S9+U9+W9+Y9+AA9+AC9+AE9+AG9+AI9+AK9+AM9+AO9+AQ9+AS9+AU9+AW9+AY9+BA9+BC9+BE9+BG9+BI9+BK9+BM9+BO9+BQ9+BS9+BU9+BW9+BY9+CA9+CE270 -> 220600 | F9: =H9+J9+L9+CD270+N9+P9+R9+T9+V9+X9+Z9+AB9+AD9+AF9+AH9+AJ9+AL9+AN9+AP9+AR9+AT9+AV9+AX9+AZ9+BB9+BD9+BF9+BH9+BJ9+BL9+BN9+BP9+BR9+BT9+BV9+BX9+BZ9+CB9+CF270 -> 220600 | M9: 220600 | AT9: 220600
A10: 5 | B10: 46023 | C10: Shipping | D10: =F10-E10 -> 0 | E10: =G10+I10+CC271+K10+M10+O10+Q10+S10+U10+W10+Y10+AA10+AC10+AE10+AG10+AI10+AK10+AM10+AO10+AQ10+AS10+AU10+AW10+AY10+BA10+BC10+BE10+BG10+BI10+BK10+BM10+BO10+BQ10+BS10+BU10+BW10+BY10+CA10+CE271 -> 3140 | F10: =H10+J10+L10+CD271+N10+P10+R10+T10+V10+X10+Z10+AB10+AD10+AF10+AH10+AJ10+AL10+AN10+AP10+AR10+AT10+AV10+AX10+AZ10+BB10+BD10+BF10+BH10+BJ10+BL10+BN10+BP10+BR10+BT10+BV10+BX10+BZ10+CB10+CF271 -> 3140 | G10: 3140 | AN10: 3140
A11: 6 | B11: 46023 | C11: Pickup | D11: =F11-E11 -> 0 | E11: =G11+I11+CC276+K11+M11+O11+Q11+S11+U11+W11+Y11+AA11+AC11+AE11+AG11+AI11+AK11+AM11+AO11+AQ11+AS11+AU11+AW11+AY11+BA11+BC11+BE11+BG11+BI11+BK11+BM11+BO11+BQ11+BS11+BU11+BW11+BY11+CA11+CE276 -> 386434 | F11: =H11+J11+L11+CD276+N11+P11+R11+T11+V11+X11+Z11+AB11+AD11+AF11+AH11+AJ11+AL11+AN11+AP11+AR11+AT11+AV11+AX11+AZ11+BB11+BD11+BF11+BH11+BJ11+BL11+BN11+BP11+BR11+BT11+BV11+BX11+BZ11+CB11+CF276 -> 386434 | AK11: 386434 | AR11: 386434
A12: 7 | B12: 46023 | C12: Receving | D12: =F12-E12 -> 0 | E12: =G12+I12+CC277+K12+M12+O12+Q12+S12+U12+W12+Y12+AA12+AC12+AE12+AG12+AI12+AK12+AM12+AO12+AQ12+AS12+AU12+AW12+AY12+BA12+BC12+BE12+BG12+BI12+BK12+BM12+BO12+BQ12+BS12+BU12+BW12+BY12+CA12+CE277 -> 119260 | F12: =H12+J12+L12+CD277+N12+P12+R12+T12+V12+X12+Z12+AB12+AD12+AF12+AH12+AJ12+AL12+AN12+AP12+AR12+AT12+AV12+AX12+AZ12+BB12+BD12+BF12+BH12+BJ12+BL12+BN12+BP12+BR12+BT12+BV12+BX12+BZ12+CB12+CF277 -> 119260 | H12: 34225 | R12: 36240 | T12: 2699 | AQ12: 119260 | BT12: 17598 | BV12: 28498
A13: 8 | B13: 46023 | C13: Refund | D13: =F13-E13 -> 0 | E13: =G13+I13+CC278+K13+M13+O13+Q13+S13+U13+W13+Y13+AA13+AC13+AE13+AG13+AI13+AK13+AM13+AO13+AQ13+AS13+AU13+AW13+AY13+BA13+BC13+BE13+BG13+BI13+BK13+BM13+BO13+BQ13+BS13+BU13+BW13+BY13+CA13+CE278 -> 0 | F13: =H13+J13+L13+CD278+N13+P13+R13+T13+V13+X13+Z13+AB13+AD13+AF13+AH13+AJ13+AL13+AN13+AP13+AR13+AT13+AV13+AX13+AZ13+BB13+BD13+BF13+BH13+BJ13+BL13+BN13+BP13+BR13+BT13+BV13+BX13+BZ13+CB13+CF278 -> 0
A14: 9 | B14: 46023 | C14: inventory | D14: =F14-E14 -> 0 | E14: =G14+I14+CC279+K14+M14+O14+Q14+S14+U14+W14+Y14+AA14+AC14+AE14+AG14+AI14+AK14+AM14+AO14+AQ14+AS14+AU14+AW14+AY14+BA14+BC14+BE14+BG14+BI14+BK14+BM14+BO14+BQ14+BS14+BU14+BW14+BY14+CA14+CE279 -> 128400 | F14: =H14+J14+L14+CD279+N14+P14+R14+T14+V14+X14+Z14+AB14+AD14+AF14+AH14+AJ14+AL14+AN14+AP14+AR14+AT14+AV14+AX14+AZ14+BB14+BD14+BF14+BH14+BJ14+BL14+BN14+BP14+BR14+BT14+BV14+BX14+BZ14+CB14+CF279 -> 128400 | N14: 128400 | AU14: 128400
A15: 10 | B15: 46023 | C15: Saleries | D15: =F15-E15 -> 0 | E15: =G15+I15+CC280+K15+M15+O15+Q15+S15+U15+W15+Y15+AA15+AC15+AE15+AG15+AI15+AK15+AM15+AO15+AQ15+AS15+AU15+AW15+AY15+BA15+BC15+BE15+BG15+BI15+BK15+BM15+BO15+BQ15+BS15+BU15+BW15+BY15+CA15+CE280 -> 271260 | F15: =H15+J15+L15+CD280+N15+P15+R15+T15+V15+X15+Z15+AB15+AD15+AF15+AH15+AJ15+AL15+AN15+AP15+AR15+AT15+AV15+AX15+AZ15+BB15+BD15+BF15+BH15+BJ15+BL15+BN15+BP15+BR15+BT15+BV15+BX15+BZ15+CB15+CF280 -> 271260 | G15: 271260 | AP15: 271260
A16: 11 | B16: 46023 | C16: General expenses | D16: =F16-E16 -> 0 | E16: =G16+I16+CC277+K16+M16+O16+Q16+S16+U16+W16+Y16+AA16+AC16+AE16+AG16+AI16+AK16+AM16+AO16+AQ16+AS16+AU16+AW16+AY16+BA16+BC16+BE16+BG16+BI16+BK16+BM16+BO16+BQ16+BS16+BU16+BW16+BY16+CA16+CE277 -> 24525 | F16: =H16+J16+L16+CD277+N16+P16+R16+T16+V16+X16+Z16+AB16+AD16+AF16+AH16+AJ16+AL16+AN16+AP16+AR16+AT16+AV16+AX16+AZ16+BB16+BD16+BF16+BH16+BJ16+BL16+BN16+BP16+BR16+BT16+BV16+BX16+BZ16+CB16+CF277 -> 24525 | G16: 24525 | AP16: 24525
A17: 12 | B17: 46023 | C17: رد سلف | D17: =F17-E17 -> 0 | E17: =G17+I17+CC278+K17+M17+O17+Q17+S17+U17+W17+Y17+AA17+AC17+AE17+AG17+AI17+AK17+AM17+AO17+AQ17+AS17+AU17+AW17+AY17+BA17+BC17+BE17+BG17+BI17+BK17+BM17+BO17+BQ17+BS17+BU17+BW17+BY17+CA17+CE278 -> 7500 | F17: =H17+J17+L17+CD278+N17+P17+R17+T17+V17+X17+Z17+AB17+AD17+AF17+AH17+AJ17+AL17+AN17+AP17+AR17+AT17+AV17+AX17+AZ17+BB17+BD17+BF17+BH17+BJ17+BL17+BN17+BP17+BR17+BT17+BV17+BX17+BZ17+CB17+CF278 -> 7500 | H17: 7500 | BQ17: 7500
A18: 1 | B18: 46024 | C18: Sales | D18: =F18-E18 -> 0 | E18: =G18+I18+CC279+K18+M18+O18+Q18+S18+U18+W18+Y18+AA18+AC18+AE18+AG18+AI18+AK18+AM18+AO18+AQ18+AS18+AU18+AW18+AY18+BA18+BC18+BE18+BG18+BI18+BK18+BM18+BO18+BQ18+BS18+BU18+BW18+BY18+CA18+CE279 -> 519449 | F18: =H18+J18+L18+CD279+N18+P18+R18+T18+V18+X18+Z18+AB18+AD18+AF18+AH18+AJ18+AL18+AN18+AP18+AR18+AT18+AV18+AX18+AZ18+BB18+BD18+BF18+BH18+BJ18+BL18+BN18+BP18+BR18+BT18+BV18+BX18+BZ18+CB18+CF279 -> 519449 | O18: 473227 | AK18: 46222 | AL18: 473227 | AX18: 46222
A19: 2 | B19: 46024 | C19: Returns | D19: =F19-E19 -> 0 | E19: =G19+I19+CC280+K19+M19+O19+Q19+S19+U19+W19+Y19+AA19+AC19+AE19+AG19+AI19+AK19+AM19+AO19+AQ19+AS19+AU19+AW19+AY19+BA19+BC19+BE19+BG19+BI19+BK19+BM19+BO19+BQ19+BS19+BU19+BW19+BY19+CA19+CE280 -> 0 | F19: =H19+J19+L19+CD280+N19+P19+R19+T19+V19+X19+Z19+AB19+AD19+AF19+AH19+AJ19+AL19+AN19+AP19+AR19+AT19+AV19+AX19+AZ19+BB19+BD19+BF19+BH19+BJ19+BL19+BN19+BP19+BR19+BT19+BV19+BX19+BZ19+CB19+CF280 -> 0
A20: 3 | B20: 46024 | C20: Returns Cost | D20: =F20-E20 -> 0 | E20: =G20+I20+CC281+K20+M20+O20+Q20+S20+U20+W20+Y20+AA20+AC20+AE20+AG20+AI20+AK20+AM20+AO20+AQ20+AS20+AU20+AW20+AY20+BA20+BC20+BE20+BG20+BI20+BK20+BM20+BO20+BQ20+BS20+BU20+BW20+BY20+CA20+CE281 -> 0 | F20: =H20+J20+L20+CD281+N20+P20+R20+T20+V20+X20+Z20+AB20+AD20+AF20+AH20+AJ20+AL20+AN20+AP20+AR20+AT20+AV20+AX20+AZ20+BB20+BD20+BF20+BH20+BJ20+BL20+BN20+BP20+BR20+BT20+BV20+BX20+BZ20+CB20+CF281 -> 0
A21: 4 | B21: 46024 | C21: Cost | D21: =F21-E21 -> 0 | E21: =G21+I21+CC283+K21+M21+O21+Q21+S21+U21+W21+Y21+AA21+AC21+AE21+AG21+AI21+AK21+AM21+AO21+AQ21+AS21+AU21+AW21+AY21+BA21+BC21+BE21+BG21+BI21+BK21+BM21+BO21+BQ21+BS21+BU21+BW21+BY21+CA21+CE283 -> 200320 | F21: =H21+J21+L21+CD283+N21+P21+R21+T21+V21+X21+Z21+AB21+AD21+AF21+AH21+AJ21+AL21+AN21+AP21+AR21+AT21+AV21+AX21+AZ21+BB21+BD21+BF21+BH21+BJ21+BL21+BN21+BP21+BR21+BT21+BV21+BX21+BZ21+CB21+CF283 -> 200320 | M21: 200320 | AT21: 200320
A22: 5 | B22: 46024 | C22: Shipping | D22: =F22-E22 -> 0 | E22: =G22+I22+CC284+K22+M22+O22+Q22+S22+U22+W22+Y22+AA22+AC22+AE22+AG22+AI22+AK22+AM22+AO22+AQ22+AS22+AU22+AW22+AY22+BA22+BC22+BE22+BG22+BI22+BK22+BM22+BO22+BQ22+BS22+BU22+BW22+BY22+CA22+CE284 -> 0 | F22: =H22+J22+L22+CD284+N22+P22+R22+T22+V22+X22+Z22+AB22+AD22+AF22+AH22+AJ22+AL22+AN22+AP22+AR22+AT22+AV22+AX22+AZ22+BB22+BD22+BF22+BH22+BJ22+BL22+BN22+BP22+BR22+BT22+BV22+BX22+BZ22+CB22+CF284 -> 0
A23: 6 | B23: 46024 | C23: Pickup | D23: =F23-E23 -> 0 | E23: =G23+I23+CC285+K23+M23+O23+Q23+S23+U23+W23+Y23+AA23+AC23+AE23+AG23+AI23+AK23+AM23+AO23+AQ23+AS23+AU23+AW23+AY23+BA23+BC23+BE23+BG23+BI23+BK23+BM23+BO23+BQ23+BS23+BU23+BW23+BY23+CA23+CE285 -> 0 | F23: =H23+J23+L23+CD285+N23+P23+R23+T23+V23+X23+Z23+AB23+AD23+AF23+AH23+AJ23+AL23+AN23+AP23+AR23+AT23+AV23+AX23+AZ23+BB23+BD23+BF23+BH23+BJ23+BL23+BN23+BP23+BR23+BT23+BV23+BX23+BZ23+CB23+CF285 -> 0
A24: 7 | B24: 46024 | C24: Receving | D24: =F24-E24 -> 0 | E24: =G24+I24+CC285+K24+M24+O24+Q24+S24+U24+W24+Y24+AA24+AC24+AE24+AG24+AI24+AK24+AM24+AO24+AQ24+AS24+AU24+AW24+AY24+BA24+BC24+BE24+BG24+BI24+BK24+BM24+BO24+BQ24+BS24+BU24+BW24+BY24+CA24+CE285 -> 49795 | F24: =H24+J24+L24+CD285+N24+P24+R24+T24+V24+X24+Z24+AB24+AD24+AF24+AH24+AJ24+AL24+AN24+AP24+AR24+AT24+AV24+AX24+AZ24+BB24+BD24+BF24+BH24+BJ24+BL24+BN24+BP24+BR24+BT24+BV24+BX24+BZ24+CB24+CF285 -> 49795 | T24: 25248 | V24: 3999 | AQ24: 49795 | BT24: 20548
A25: 8 | B25: 46024 | C25: Refund | D25: =F25-E25 -> 0 | E25: =G25+I25+CC284+K25+M25+O25+Q25+S25+U25+W25+Y25+AA25+AC25+AE25+AG25+AI25+AK25+AM25+AO25+AQ25+AS25+AU25+AW25+AY25+BA25+BC25+BE25+BG25+BI25+BK25+BM25+BO25+BQ25+BS25+BU25+BW25+BY25+CA25+CE284 -> 0 | F25: =H25+J25+L25+CD284+N25+P25+R25+T25+V25+X25+Z25+AB25+AD25+AF25+AH25+AJ25+AL25+AN25+AP25+AR25+AT25+AV25+AX25+AZ25+BB25+BD25+BF25+BH25+BJ25+BL25+BN25+BP25+BR25+BT25+BV25+BX25+BZ25+CB25+CF284 -> 0
A26: 9 | B26: 46024 | C26: inventory | D26: =F26-E26 -> 0 | E26: =G26+I26+CC285+K26+M26+O26+Q26+S26+U26+W26+Y26+AA26+AC26+AE26+AG26+AI26+AK26+AM26+AO26+AQ26+AS26+AU26+AW26+AY26+BA26+BC26+BE26+BG26+BI26+BK26+BM26+BO26+BQ26+BS26+BU26+BW26+BY26+CA26+CE285 -> 0 | F26: =H26+J26+L26+CD285+N26+P26+R26+T26+V26+X26+Z26+AB26+AD26+AF26+AH26+AJ26+AL26+AN26+AP26+AR26+AT26+AV26+AX26+AZ26+BB26+BD26+BF26+BH26+BJ26+BL26+BN26+BP26+BR26+BT26+BV26+BX26+BZ26+CB26+CF285 -> 0
A27: 1 | B27: 46025 | C27: Sales | D27: =F27-E27 -> 0 | E27: =G27+I27+CC286+K27+M27+O27+Q27+S27+U27+W27+Y27+AA27+AC27+AE27+AG27+AI27+AK27+AM27+AO27+AQ27+AS27+AU27+AW27+AY27+BA27+BC27+BE27+BG27+BI27+BK27+BM27+BO27+BQ27+BS27+BU27+BW27+BY27+CA27+CE286 -> 583224 | F27: =H27+J27+L27+CD286+N27+P27+R27+T27+V27+X27+Z27+AB27+AD27+AF27+AH27+AJ27+AL27+AN27+AP27+AR27+AT27+AV27+AX27+AZ27+BB27+BD27+BF27+BH27+BJ27+BL27+BN27+BP27+BR27+BT27+BV27+BX27+BZ27+CB27+CF286 -> 583224 | O27: 536134 | AK27: 47090 | AL27: 536134 | AX27: 47090
A28: 2 | B28: 46025 | C28: Returns | D28: =F28-E28 -> 0 | E28: =G28+I28+CC287+K28+M28+O28+Q28+S28+U28+W28+Y28+AA28+AC28+AE28+AG28+AI28+AK28+AM28+AO28+AQ28+AS28+AU28+AW28+AY28+BA28+BC28+BE28+BG28+BI28+BK28+BM28+BO28+BQ28+BS28+BU28+BW28+BY28+CA28+CE287 -> 128236 | F28: =H28+J28+L28+CD287+N28+P28+R28+T28+V28+X28+Z28+AB28+AD28+AF28+AH28+AJ28+AL28+AN28+AP28+AR28+AT28+AV28+AX28+AZ28+BB28+BD28+BF28+BH28+BJ28+BL28+BN28+BP28+BR28+BT28+BV28+BX28+BZ28+CB28+CF287 -> 128236 | P28: 128236 | AQ28: 128236
A29: 3 | B29: 46025 | C29: Returns Cost | D29: =F29-E29 -> 0 | E29: =G29+I29+CC291+K29+M29+O29+Q29+S29+U29+W29+Y29+AA29+AC29+AE29+AG29+AI29+AK29+AM29+AO29+AQ29+AS29+AU29+AW29+AY29+BA29+BC29+BE29+BG29+BI29+BK29+BM29+BO29+BQ29+BS29+BU29+BW29+BY29+CA29+CE291 -> 57400 | F29: =H29+J29+L29+CD291+N29+P29+R29+T29+V29+X29+Z29+AB29+AD29+AF29+AH29+AJ29+AL29+AN29+AP29+AR29+AT29+AV29+AX29+AZ29+BB29+BD29+BF29+BH29+BJ29+BL29+BN29+BP29+BR29+BT29+BV29+BX29+BZ29+CB29+CF291 -> 57400 | N29: 57400 | AS29: 57400
A30: 4 | B30: 46025 | C30: Cost | D30: =F30-E30 -> 0 | E30: =G30+I30+CC292+K30+M30+O30+Q30+S30+U30+W30+Y30+AA30+AC30+AE30+AG30+AI30+AK30+AM30+AO30+AQ30+AS30+AU30+AW30+AY30+BA30+BC30+BE30+BG30+BI30+BK30+BM30+BO30+BQ30+BS30+BU30+BW30+BY30+CA30+CE292 -> 221700 | F30: =H30+J30+L30+CD292+N30+P30+R30+T30+V30+X30+Z30+AB30+AD30+AF30+AH30+AJ30+AL30+AN30+AP30+AR30+AT30+AV30+AX30+AZ30+BB30+BD30+BF30+BH30+BJ30+BL30+BN30+BP30+BR30+BT30+BV30+BX30+BZ30+CB30+CF292 -> 221700 | M30: 221700 | AT30: 221700
A31: 5 | B31: 46025 | C31: Shipping | D31: =F31-E31 -> 0 | E31: =G31+I31+CC293+K31+M31+O31+Q31+S31+U31+W31+Y31+AA31+AC31+AE31+AG31+AI31+AK31+AM31+AO31+AQ31+AS31+AU31+AW31+AY31+BA31+BC31+BE31+BG31+BI31+BK31+BM31+BO31+BQ31+BS31+BU31+BW31+BY31+CA31+CE293 -> 2115 | F31: =H31+J31+L31+CD293+N31+P31+R31+T31+V31+X31+Z31+AB31+AD31+AF31+AH31+AJ31+AL31+AN31+AP31+AR31+AT31+AV31+AX31+AZ31+BB31+BD31+BF31+BH31+BJ31+BL31+BN31+BP31+BR31+BT31+BV31+BX31+BZ31+CB31+CF293 -> 2115 | G31: 2115 | AN31: 2115
A32: 6 | B32: 46025 | C32: Pickup | D32: =F32-E32 -> 0 | E32: =G32+I32+CC294+K32+M32+O32+Q32+S32+U32+W32+Y32+AA32+AC32+AE32+AG32+AI32+AK32+AM32+AO32+AQ32+AS32+AU32+AW32+AY32+BA32+BC32+BE32+BG32+BI32+BK32+BM32+BO32+BQ32+BS32+BU32+BW32+BY32+CA32+CE294 -> 670751 | F32: =H32+J32+L32+CD294+N32+P32+R32+T32+V32+X32+Z32+AB32+AD32+AF32+AH32+AJ32+AL32+AN32+AP32+AR32+AT32+AV32+AX32+AZ32+BB32+BD32+BF32+BH32+BJ32+BL32+BN32+BP32+BR32+BT32+BV32+BX32+BZ32+CB32+CF294 -> 670751 | AK32: 670751 | AR32: 670751
A33: 7 | B33: 46025 | C33: Receving | D33: =F33-E33 -> 0 | E33: =G33+I33+CC294+K33+M33+O33+Q33+S33+U33+W33+Y33+AA33+AC33+AE33+AG33+AI33+AK33+AM33+AO33+AQ33+AS33+AU33+AW33+AY33+BA33+BC33+BE33+BG33+BI33+BK33+BM33+BO33+BQ33+BS33+BU33+BW33+BY33+CA33+CE294 -> 201617 | F33: =H33+J33+L33+CD294+N33+P33+R33+T33+V33+X33+Z33+AB33+AD33+AF33+AH33+AJ33+AL33+AN33+AP33+AR33+AT33+AV33+AX33+AZ33+BB33+BD33+BF33+BH33+BJ33+BL33+BN33+BP33+BR33+BT33+BV33+BX33+BZ33+CB33+CF294 -> 201617 | H33: 69474 | J33: 16600 | R33: 32897 | V33: 21499 | AQ33: 201617 | BV33: 61147
A34: 8 | B34: 46025 | C34: Refund | D34: =F34-E34 -> 0 | E34: =G34+I34+CC295+K34+M34+O34+Q34+S34+U34+W34+Y34+AA34+AC34+AE34+AG34+AI34+AK34+AM34+AO34+AQ34+AS34+AU34+AW34+AY34+BA34+BC34+BE34+BG34+BI34+BK34+BM34+BO34+BQ34+BS34+BU34+BW34+BY34+CA34+CE295 -> 15615 | F34: =H34+J34+L34+CD295+N34+P34+R34+T34+V34+X34+Z34+AB34+AD34+AF34+AH34+AJ34+AL34+AN34+AP34+AR34+AT34+AV34+AX34+AZ34+BB34+BD34+BF34+BH34+BJ34+BL34+BN34+BP34+BR34+BT34+BV34+BX34+BZ34+CB34+CF295 -> 15615 | S34: 7400 | U34: 8215 | AZ34: 15615
A35: 9 | B35: 46025 | C35: inventory | D35: =F35-E35 -> 0 | E35: =G35+I35+CC296+K35+M35+O35+Q35+S35+U35+W35+Y35+AA35+AC35+AE35+AG35+AI35+AK35+AM35+AO35+AQ35+AS35+AU35+AW35+AY35+BA35+BC35+BE35+BG35+BI35+BK35+BM35+BO35+BQ35+BS35+BU35+BW35+BY35+CA35+CE296 -> 0 | F35: =H35+J35+L35+CD296+N35+P35+R35+T35+V35+X35+Z35+AB35+AD35+AF35+AH35+AJ35+AL35+AN35+AP35+AR35+AT35+AV35+AX35+AZ35+BB35+BD35+BF35+BH35+BJ35+BL35+BN35+BP35+BR35+BT35+BV35+BX35+BZ35+CB35+CF296 -> 0
A36: 10 | B36: 46025 | C36: General expenses | D36: =F36-E36 -> 0 | E36: =G36+I36+CC297+K36+M36+O36+Q36+S36+U36+W36+Y36+AA36+AC36+AE36+AG36+AI36+AK36+AM36+AO36+AQ36+AS36+AU36+AW36+AY36+BA36+BC36+BE36+BG36+BI36+BK36+BM36+BO36+BQ36+BS36+BU36+BW36+BY36+CA36+CE297 -> 18725 | F36: =H36+J36+L36+CD297+N36+P36+R36+T36+V36+X36+Z36+AB36+AD36+AF36+AH36+AJ36+AL36+AN36+AP36+AR36+AT36+AV36+AX36+AZ36+BB36+BD36+BF36+BH36+BJ36+BL36+BN36+BP36+BR36+BT36+BV36+BX36+BZ36+CB36+CF297 -> 18725 | G36: 18725 | AP36: 18725
A37: 1 | B37: 46026 | C37: Sales | D37: =F37-E37 -> 0 | E37: =G37+I37+CC293+K37+M37+O37+Q37+S37+U37+W37+Y37+AA37+AC37+AE37+AG37+AI37+AK37+AM37+AO37+AQ37+AS37+AU37+AW37+AY37+BA37+BC37+BE37+BG37+BI37+BK37+BM37+BO37+BQ37+BS37+BU37+BW37+BY37+CA37+CE293 -> 851115 | F37: =H37+J37+L37+CD293+N37+P37+R37+T37+V37+X37+Z37+AB37+AD37+AF37+AH37+AJ37+AL37+AN37+AP37+AR37+AT37+AV37+AX37+AZ37+BB37+BD37+BF37+BH37+BJ37+BL37+BN37+BP37+BR37+BT37+BV37+BX37+BZ37+CB37+CF293 -> 851115 | O37: 782616 | AK37: 68499 | AL37: 782616 | AX37: 68499
A38: 2 | B38: 46026 | C38: Returns | D38: =F38-E38 -> 0 | E38: =G38+I38+CC284+K38+M38+O38+Q38+S38+U38+W38+Y38+AA38+AC38+AE38+AG38+AI38+AK38+AM38+AO38+AQ38+AS38+AU38+AW38+AY38+BA38+BC38+BE38+BG38+BI38+BK38+BM38+BO38+BQ38+BS38+BU38+BW38+BY38+CA38+CE284 -> 714375 | F38: =H38+J38+L38+CD284+N38+P38+R38+T38+V38+X38+Z38+AB38+AD38+AF38+AH38+AJ38+AL38+AN38+AP38+AR38+AT38+AV38+AX38+AZ38+BB38+BD38+BF38+BH38+BJ38+BL38+BN38+BP38+BR38+BT38+BV38+BX38+BZ38+CB38+CF284 -> 714375 | P38: 714375 | AQ38: 714375
A39: 3 | B39: 46026 | C39: Returns Cost | D39: =F39-E39 -> 0 | E39: =G39+I39+CC285+K39+M39+O39+Q39+S39+U39+W39+Y39+AA39+AC39+AE39+AG39+AI39+AK39+AM39+AO39+AQ39+AS39+AU39+AW39+AY39+BA39+BC39+BE39+BG39+BI39+BK39+BM39+BO39+BQ39+BS39+BU39+BW39+BY39+CA39+CE285 -> 342720 | F39: =H39+J39+L39+CD285+N39+P39+R39+T39+V39+X39+Z39+AB39+AD39+AF39+AH39+AJ39+AL39+AN39+AP39+AR39+AT39+AV39+AX39+AZ39+BB39+BD39+BF39+BH39+BJ39+BL39+BN39+BP39+BR39+BT39+BV39+BX39+BZ39+CB39+CF285 -> 342720 | N39: 342720 | AS39: 342720
A40: 4 | B40: 46026 | C40: Cost | D40: =F40-E40 -> 0 | E40: =G40+I40+CC286+K40+M40+O40+Q40+S40+U40+W40+Y40+AA40+AC40+AE40+AG40+AI40+AK40+AM40+AO40+AQ40+AS40+AU40+AW40+AY40+BA40+BC40+BE40+BG40+BI40+BK40+BM40+BO40+BQ40+BS40+BU40+BW40+BY40+CA40+CE286 -> 358330 | F40: =H40+J40+L40+CD286+N40+P40+R40+T40+V40+X40+Z40+AB40+AD40+AF40+AH40+AJ40+AL40+AN40+AP40+AR40+AT40+AV40+AX40+AZ40+BB40+BD40+BF40+BH40+BJ40+BL40+BN40+BP40+BR40+BT40+BV40+BX40+BZ40+CB40+CF286 -> 358330 | M40: 358330 | AT40: 358330
...

Sheet Trial balance
A1: Desscription | B1: Total journal entry | D1: Balance
B2: Credit | C2: Debit | D2: Credit | E2: Debit | H2: IN Come steetment | I2: قائمة الدخل | L2: BaLance Sheet الميزانية
A3: ='American journal voucher'!$G$3 -> Cash | B3: ='American journal voucher'!G5098 -> 5066015 | C3: ='American journal voucher'!H5098 -> 5125814 | D3: =IF(B3>C3,B3-C3,0) -> 0 | E3: =IF(C3>B3,C3-B3,0) -> 59799 | L3: Assets
A4: ='American journal voucher'!$I$3 -> Bank | B4: ='American journal voucher'!I5098 -> 0 | C4: ='American journal voucher'!J5098 -> 388408 | D4: =IF(B4>C4,B4-C4,0) -> 0 | E4: =IF(C4>B4,C4-B4,0) -> 388408 | H4: Sales | I4: =D7 -> 23305332 | L4: Fixed assets | M4: 0
A5: ='American journal voucher'!$K$3 -> Vodafon Cash | B5: ='American journal voucher'!K5098 -> 301199.8 | C5: ='American journal voucher'!L5098 -> 267075 | D5: =IF(B5>C5,B5-C5,0) -> 34124.8 | E5: =IF(C5>B5,C5-B5,0) -> 0 | L5: Cash | M5: =E3 -> 59799
A6: ='American journal voucher'!$M$3 -> Inventory | B6: ='American journal voucher'!M5098 -> 21421165 | C6: ='American journal voucher'!N5098 -> 22508915 | D6: =IF(B6>C6,B6-C6,0) -> 0 | E6: =IF(C6>B6,C6-B6,0) -> 1087750 | H6: ='[2]American journal voucher'!$AW$3 -> Discount | I6: =E24 -> 5121874.9 | L6: BANK | M6: =E4 -> 388408
A7: ='American journal voucher'!$O$3 -> Sales | B7: ='American journal voucher'!O5098 -> 47869388 | C7: ='American journal voucher'!P5098 -> 24564056 | D7: =IF(B7>C7,B7-C7,0) -> 23305332 | E7: =IF(C7>B7,C7-B7,0) -> 0 | H7: Refund | I7: =E25 -> 944383 | L7: V.F
A8: ='American journal voucher'!$Q$3 -> Instapay 2 | B8: ='American journal voucher'!Q5098 -> 480856 | C8: ='American journal voucher'!R5098 -> 3635524 | D8: =IF(B8>C8,B8-C8,0) -> 0 | E8: =IF(C8>B8,C8-B8,0) -> 3154668 | L8: INVENTORY | M8: =E6 -> 1087750
A9: ='American journal voucher'!$S$3 -> Paymob | B9: ='American journal voucher'!S5098 -> 205991 | C9: ='American journal voucher'!T5098 -> 3515583 | D9: =IF(B9>C9,B9-C9,0) -> 0 | E9: =IF(C9>B9,C9-B9,0) -> 3309592 | H9: net sales | I9: =I4-I6-I7 -> 17239074 | L9: INSTAPAY | M9: =E36 -> 2696489
A10: ='American journal voucher'!$U$3 -> Value | B10: ='American journal voucher'!U5098 -> 204775 | C10: ='American journal voucher'!V5098 -> 2037083 | D10: =IF(B10>C10,B10-C10,0) -> 0 | E10: =IF(C10>B10,C10-B10,0) -> 1832308 | H10: Cost | I10: =E22 -> 8786830 | L10: INSTAPAY 2 | M10: =E8 -> 3154668
A11: ='American journal voucher'!$W$3 -> Gift Card | B11: ='American journal voucher'!W5098 -> 20372 | C11: ='American journal voucher'!X5098 -> 75267 | D11: =IF(B11>C11,B11-C11,0) -> 0 | E11: =IF(C11>B11,C11-B11,0) -> 54895 | L11: Paymob | M11: =E9 -> 3309592
A12: ='American journal voucher'!$Y$3 -> Share holder's | B12: ='American journal voucher'!Y5098 -> 5585853 | C12: ='American journal voucher'!Z5098 -> 6000 | D12: =IF(B12>C12,B12-C12,0) -> 5579853 | E12: =IF(C12>B12,C12-B12,0) -> 0 | H12: Gross Profit | I12: =I9-I10 -> 8452243.9 | L12: Value | M12: =E10 -> 1832308
A13: ='American journal voucher'!$AA$3 -> Depreciation | B13: ='American journal voucher'!AA5098 -> 0 | C13: ='American journal voucher'!AB5098 -> 0 | D13: =IF(B13>C13,B13-C13,0) -> 0 | E13: =IF(C13>B13,C13-B13,0) -> 0 | L13: Gift Card | M13: =E11 -> 54895
A14: ='American journal voucher'!$AC$3 -> Capital | B14: ='American journal voucher'!AC5098 -> 0 | C14: ='American journal voucher'!AD5098 -> 0 | D14: =IF(B14>C14,B14-C14,0) -> 0 | E14: =IF(C14>B14,C14-B14,0) -> 0 | H14: EX | L14: SYMPL | M14: =E36 -> 2696489
A15: ='American journal voucher'!$AE$3 -> Retained earning | B15: ='American journal voucher'!AE5098 -> 0 | C15: ='American journal voucher'!AF5098 -> 0 | D15: =IF(B15>C15,B15-C15,0) -> 0 | E15: =IF(C15>B15,C15-B15,0) -> 0 | H15: Administrative Expenses | I15: =E20 -> 1170982 | L15: Opreation
A16: ='American journal voucher'!$AG$3 -> Prepared Expenses | B16: ='American journal voucher'!AG5098 -> 0 | C16: ='American journal voucher'!AH5098 -> 0 | D16: =IF(B16>C16,B16-C16,0) -> 0 | E16: =IF(C16>B16,C16-B16,0) -> 0 | H16: Shipping | I16: =E19 -> 326070
A17: ='American journal voucher'!$AI$3 -> Fixed assets | B17: ='American journal voucher'!AI5098 -> 0 | C17: ='American journal voucher'!AJ5098 -> 0 | D17: =IF(B17>C17,B17-C17,0) -> 0 | E17: =IF(C17>B17,C17-B17,0) -> 0 | H17: Markting | I17: =E27 -> 5863798.8 | L17: Tootal Assets
A18: ='American journal voucher'!$AK$3 -> Opreation | B18: ='American journal voucher'!AK5098 -> 52353184 | C18: ='American journal voucher'!AL5098 -> 47869388 | D18: =IF(B18>C18,B18-C18,0) -> 4483795.9 | E18: =IF(C18>B18,C18-B18,0) -> 0 | H18: Tootal Ex | I18: =I15+I16+I17 -> 7360850.8 | L18: Capital
A19: ='American journal voucher'!$AM$3 -> Shipping | B19: ='American journal voucher'!AM5098 -> 0 | C19: ='American journal voucher'!AN5098 -> 326070 | D19: =IF(B19>C19,B19-C19,0) -> 0 | E19: =IF(C19>B19,C19-B19,0) -> 326070 | L19: Share holders
A20: ='American journal voucher'!$AO$3 -> Administrative Expenses | B20: ='American journal voucher'!AO5098 -> 670 | C20: ='American journal voucher'!AP5098 -> 1171652 | D20: =IF(B20>C20,B20-C20,0) -> 0 | E20: =IF(C20>B20,C20-B20,0) -> 1170982 | L20: Purchasing
A21: ='American journal voucher'!$AQ$3 -> Advance to employees | B21: ='American journal voucher'!AQ5098 -> 43140847 | C21: ='American journal voucher'!AR5098 -> 47231309 | D21: =IF(B21>C21,B21-C21,0) -> 0 | E21: =IF(C21>B21,C21-B21,0) -> 4090461.8 | L21: P&l
A22: ='American journal voucher'!$AS$3 -> Cost | B22: ='American journal voucher'!AS5098 -> 12634335 | C22: ='American journal voucher'!AT5098 -> 21421165 | D22: =IF(B22>C22,B22-C22,0) -> 0 | E22: =IF(C22>B22,C22-B22,0) -> 8786830 | H22: NET Profit | I22: =I12-I18 -> 1091393.1 | L22: Advance to employees
A23: ='American journal voucher'!$AU$3 -> Purchasing | B23: ='American journal voucher'!AU5098 -> 9874580 | C23: ='American journal voucher'!AV5098 -> 3634400 | D23: =IF(B23>C23,B23-C23,0) -> 6240180 | E23: =IF(C23>B23,C23-B23,0) -> 0 | L23: Net Profit
A24: ='American journal voucher'!$AW$3 -> Discount | B24: ='American journal voucher'!AW5098 -> 0 | C24: ='American journal voucher'!AX5098 -> 5121874.9 | D24: =IF(B24>C24,B24-C24,0) -> 0 | E24: =IF(C24>B24,C24-B24,0) -> 5121874.9 | L24: Tootal Assets
A25: ='American journal voucher'!$AY$3 -> Refund | B25: ='American journal voucher'!AY5098 -> 0 | C25: ='American journal voucher'!AZ5098 -> 944383 | D25: =IF(B25>C25,B25-C25,0) -> 0 | E25: =IF(C25>B25,C25-B25,0) -> 944383
A26: ='American journal voucher'!$BA$3 -> Suppliers | B26: ='American journal voucher'!BA5098 -> 0 | C26: ='American journal voucher'!BB5098 -> 0 | D26: =IF(B26>C26,B26-C26,0) -> 0 | E26: =IF(C26>B26,C26-B26,0) -> 0
A27: ='American journal voucher'!$BC$3 -> Markting | B27: ='American journal voucher'!BC5098 -> 0 | C27: ='American journal voucher'!BD5098 -> 5863798.8 | D27: =IF(B27>C27,B27-C27,0) -> 0 | E27: =IF(C27>B27,C27-B27,0) -> 5863798.8
A28: ='American journal voucher'!$BE$3 -> Bank Masr | B28: ='American journal voucher'!BE5098 -> 0 | C28: ='American journal voucher'!BF5098 -> 0 | D28: =IF(B28>C28,B28-C28,0) -> 0 | E28: =IF(C28>B28,C28-B28,0) -> 0
A29: ='American journal voucher'!$BG$3 -> Bank interest | B29: ='American journal voucher'!BG5098 -> 0 | C29: ='American journal voucher'!BH5098 -> 0 | D29: =IF(B29>C29,B29-C29,0) -> 0 | E29: =IF(C29>B29,C29-B29,0) -> 0
A30: ='American journal voucher'!$BI$3 -> other Ep | B30: ='American journal voucher'!BI5098 -> 0 | C30: ='American journal voucher'!BJ5098 -> 0 | D30: =IF(B30>C30,B30-C30,0) -> 0 | E30: =IF(C30>B30,C30-B30,0) -> 0
A31: ='American journal voucher'!$BK$3 -> Bank interest cr | B31: ='American journal voucher'!BK5098 -> 0 | C31: ='American journal voucher'!BL5098 -> 0 | D31: =IF(B31>C31,B31-C31,0) -> 0 | E31: =IF(C31>B31,C31-B31,0) -> 0
A32: ='American journal voucher'!$BM$3 -> p&l | B32: ='American journal voucher'!BM5098 -> 0 | C32: ='American journal voucher'!BN5098 -> 0 | D32: =IF(B32>C32,B32-C32,0) -> 0 | E32: =IF(C32>B32,C32-B32,0) -> 0
A33: ='American journal voucher'!$BO$3 -> deposits revenue | B33: ='American journal voucher'!BO5098 -> 0 | C33: ='American journal voucher'!BP5098 -> 0 | D33: =IF(B33>C33,B33-C33,0) -> 0 | E33: =IF(C33>B33,C33-B33,0) -> 0
A34: ='American journal voucher'!$BQ$3 -> سلف | B34: ='American journal voucher'!BQ5098 -> 11700 | C34: ='American journal voucher'!BR5098 -> 11000 | D34: =IF(B34>C34,B34-C34,0) -> 700 | E34: =IF(C34>B34,C34-B34,0) -> 0
A35: ='American journal voucher'!$BS$3 -> SYMPL | B35: ='American journal voucher'!BS5098 -> 112242 | C35: ='American journal voucher'!BT5098 -> 867918 | D35: =IF(B35>C35,B35-C35,0) -> 0 | E35: =IF(C35>B35,C35-B35,0) -> 755676
A36: ='American journal voucher'!$BU$3 -> INSTAPAY | B36: ='American journal voucher'!BU5098 -> 0 | C36: ='American journal voucher'!BV5098 -> 2696489 | D36: =IF(B36>C36,B36-C36,0) -> 0 | E36: =IF(C36>B36,C36-B36,0) -> 2696489
A37: ='American journal voucher'!$BW$3 -> 0 | B37: ='American journal voucher'!BW5098 -> 0 | C37: ='American journal voucher'!BX5098 -> 0 | D37: =IF(B37>C37,B37-C37,0) -> 0 | E37: =IF(C37>B37,C37-B37,0) -> 0
A38: ='American journal voucher'!$BY$3 -> 0 | B38: ='American journal voucher'!BY5098 -> 0 | C38: ='American journal voucher'!BZ5098 -> 0 | D38: =IF(B38>C38,B38-C38,0) -> 0 | E38: =IF(C38>B38,C38-B38,0) -> 0
A39: ='American journal voucher'!$CA$3 -> 0 | B39: ='American journal voucher'!CA5098 -> 0 | C39: ='American journal voucher'!CB5098 -> 0 | D39: =IF(B39>C39,B39-C39,0) -> 0 | E39: =IF(C39>B39,C39-B39,0) -> 0
A40: ='American journal voucher'!$CC$3 -> 0 | B40: ='American journal voucher'!CC5106 -> 0 | C40: ='American journal voucher'!CD5106 -> 0 | D40: =IF(B40>C40,B40-C40,0) -> 0 | E40: =IF(C40>B40,C40-B40,0) -> 0
...
